1. 자원 반납과 finally  
자원 반납 문제  
```
변수1 = new 자원객체1(); // 자원 할당 
변수1.작업(); 
변수1.close(); // 자원 반납
```
위 코드에서 작업() 메소드가 에러 없이 실행된 경우  
마지막 문장에서 close() 메소드가 호출되어 자원이 반납된다.  

그러나 작업() 메소드 내부에서 exception이 발생하면,  
실행 흐름이 catch 블럭으로 점프하게 된다.  
이 경우에, 마지막 문장도 건너뛰게 되어 close() 메소드가 호출되지 않는다.  
→ 자원을 반납하지 못하는 문제 발생  

